Workbook
Name _1988: #REF!
Name _CBD02: #REF!
Name _Fill: #REF!
Name _Key1: #REF!
Name _Key2: #REF!
Name _MD5: #REF!
Name _Sort: #REF!
Name _SPR1: #REF!
Name _T2: #REF!
Name adada: #REF!
Name adda: #REF!
Name ana: #REF!
Name as: #REF!
Name asd: #REF!
Name asfs: #REF!
Name CONT02092000.4: #REF!
Name dasdasd: #REF!
Name Devoluções: #REF!
Name DIFF: #REF!
Name EEEE: #REF!
Name egterqfg23gt432: #REF!
Name ertgqetq: #REF!
Name fdsfs: #REF!
Name ffefwef: #REF!
Name FREGT: #REF!
Name fsfsgf: #REF!
Name g45h42g4tg42: #REF!
Name Gastos.com.Pessoal.Comercial: #REF!
Name Gastos.com.Pessoal.Industrial: #REF!
Name GERAL: #REF!
Name gfwegweg: #REF!
Name grewgq: #REF!
Name imob: #REF!
Name imob1: #REF!
Name jhkj: #REF!
Name klkl: #REF!
Name LANCTOS: #REF!
Name LLOYD: #REF!
Name m: #REF!
Name n: #REF!
Name nikol: #REF!
Name njo: #REF!
Name nlkp: #REF!
Name nnn: #REF!
Name PDC: #REF!
Name pinco: #REF!
Name pippo: #REF!
Name Pró.Labore: #REF!
Name qertwqrt: #REF!
Name RIC: #REF!
Name RICL: #REF!
Name RICLASS: #REF!
Name RPC: #REF!
Name S: #REF!
Name sa: #REF!
Name sadaas: #REF!
Name SPR: #REF!
Name SS: #REF!
Name t34t34t: #REF!
Name t3gtt: #REF!

Sheet Claude Log
A1: Turn # | B1: Date | C1: User Request | D1: Action Taken | E1: Details | F1: Outcome
A2: 1 | B2: 46139 | C2: Atualizar fórmulas das colunas P e T para usar as mesmas fontes de busca de X e AB (RESUMO local em vez de arquivo externo Despesas 2026). | D2: Substituí todas as fórmulas VLOOKUP em P e T que apontavam para o arquivo externo '\\192.168.1.250\...\Despesas 2026 - Detalhado.xlsx' pela fonte local RESUMO!$A$3:$M$200. | E2: 246 fórmulas atualizadas (123 em P col 2=jan; 123 em T col 3=fev). Padrão: =IFERROR(VLOOKUP($I<row>,RESUMO!$A$3:$M$200,<col>,FALSE),""). Linhas 154/155 também padronizadas para usar $I em vez de I/M. | F2: Valores recalculados conferem com originais (ex: P13=52.378,26; T13=71.719,76). P12 e T12 totalizadores OK.

Sheet Acompanhamento Orçamento
I2: Karams 2026
I3: DRE (2) | J3: 112025 | L3: 122025 | N3: 12026 | R3: 22026 | V3: 32026 | Z3: 42026 | AD3: 52026 | AH3: 62026 | AJ3: 72026 | AL3: 82026 | AN3: 92026 | AP3: 102026 | AR3: 112026 | AT3: 122026 | AW3: -27948522
J4: Orçado | L4: Orçado | N4: Orçado | P4: Realizado | R4: Orçado | T4: Realizado | V4: Orçado | X4: Realizado | Z4: Orçado | AB4: Realizado | AD4: Orçado | AF4: Realizado | AH4: Orçado | AJ4: Orçado | AL4: Orçado | AN4: Orçado | AP4: Orçado | AR4: Orçado | AT4: Orçado
J5: 45962 | K5: AV | L5: 45992 | M5: AV | N5: 46023 | O5: AV | P5: 46023 | Q5: AV | R5: 46054 | S5: AV | T5: 46054 | U5: AV | V5: 46082 | W5: AV | X5: 46082 | Y5: AV | Z5: 46113 | AA5: AV | AB5: 46113 | AC5: AV | AD5: 46143 | AE5: AV | AF5: 46143 | AG5: AV | AH5: 46174 | AI5: AV | AJ5: 46204 | AK5: AV | AL5: 46235 | AM5: AV | AN5: 46266 | AO5: AV | AP5: 46296 | AQ5: AV | AR5: 46327 | AS5: AV | AT5: 46357 | AU5: AV | AW5: 2026 | AX5: AV | AY5: Média
I6: Min disponíveis | J6: 32793.329 | L6: 25993.761 | N6: 20560.304 | R6: 28477.134 | V6: 36152.605 | Z6: 32373.389 | AD6: 34928.872 | AH6: 28747.412 | AJ6: 28861.681 | AL6: 33440.249 | AN6: 38093.595 | AP6: 38900.537 | AR6: 33860.639 | AT6: 30093.75
I7: Min ocupados | J7: 52896 | L7: 33408 | N7: 58464 | R7: 55680 | V7: 64032 | Z7: 55680 | AD7: 58464 | AH7: 61248 | AJ7: 64032 | AL7: 61248 | AN7: 61248 | AP7: 58464 | AR7: 55680 | AT7: 33408
I8: % Capacidade Ocupada | J8: 0.61995859 | L8: 0.77806997 | N8: 0.3516746 | R8: 0.51144278 | V8: 0.56460215 | Z8: 0.58141862 | AD8: 0.59744239 | AH8: 0.46936082 | AJ8: 0.4507384 | AL8: 0.54598107 | AN8: 0.62195655 | AP8: 0.66537591 | AR8: 0.6081293 | AT8: 0.90079471
C9: Mês
B10: Tipo | C10: Ini | D10: Fin | E10: Premissa | F10: Valor | H10: Responsável | I10: Faturamento | J10: 2500000 | K10: 1 | L10: 2000000 | M10: 1 | N10: 1623447 | O10: 1 | P10: 1505834 | Q10: =P10/N10-1 -> -0.072446456 | R10: 2225988 | S10: 1 | T10: 2046711.4 | U10: =T10/R10-1 -> -0.080537983 | V10: 2800428.7 | W10: 1 | X10: 2626243.4 | Y10: =X10/V10-1 -> -0.062199519 | Z10: 2446309.8 | AA10: 1 | AB10: 2327111.8 | AC10: =AB10/Z10-1 -> -0.048725636 | AD10: 2562865.1 | AE10: 1 | AF10: 430572.21 | AG10: =AF10/AD10-1 -> -0.83199576 | AH10: 2217691.5 | AI10: 1 | AJ10: 2246169.5 | AK10: 1 | AL10: 2691085.6 | AM10: 1 | AN10: 2979407.8 | AO10: 1 | AP10: 3011564.5 | AQ10: 1 | AR10: 2738571.6 | AS10: 1 | AT10: 2456470.9 | AU10: 1 | AW10: 30000000 | AX10: 1 | AY10: 2500000
I12: Deduções | J12: -194500 | K12: -0.0778 | L12: -155600 | M12: -0.0778 | N12: -126304.17 | O12: -0.0778 | P12: =SUM(P13:P19) -> 136035.24 | Q12: =IFERROR((P12*-1)/N12-1,"") -> 0.077044696 | R12: -173181.87 | S12: -0.0778 | T12: =SUM(T13:T19) -> 115564.43 | U12: =IFERROR((T12*-1)/R12-1,"") -> -0.33269902 | V12: -217873.35 | W12: -0.0778 | X12: =SUM(X13:X19) -> 169337.99 | Y12: =IFERROR((X12*-1)/V12-1,"") -> -0.2227687 | Z12: -190322.91 | AA12: -0.0778 | AB12: =SUM(AB13:AB19) -> 140077.9 | AC12: =IFERROR((AB12*-1)/Z12-1,"") -> -0.26399873 | AD12: -199390.91 | AE12: -0.0778 | AF12: =SUM(AF13:AF19) -> 0 | AG12: =IFERROR((AF12*-1)/AD12-1,"") -> -1 | AH12: -172536.4 | AI12: -0.0778 | AJ12: -174751.98 | AK12: -0.0778 | AL12: -209366.46 | AM12: -0.0778 | AN12: -231797.93 | AO12: -0.0778 | AP12: -234299.72 | AQ12: -0.0778 | AR12: -213060.87 | AS12: -0.0778 | AT12: -191113.43 | AU12: -0.0778 | AW12: -2334000 | AX12: -0.0778 | AY12: -194500
B13: % | C13: 8 | D13: 9 | E13: % 8-9 de 2025 | F13: -0.0262 | H13: Letícia | I13: Simples Nacional | J13: -65500 | K13: -0.0262 | L13: -52400 | M13: -0.0262 | N13: =P$10*$F13 -> -39452.85 | O13: -0.0262 | P13: =IFERROR(VLOOKUP($I13,RESUMO!$A$3:$M$200,2,FALSE),"") -> 52378.26 | Q13: =IFERROR((P13*-1)/N13-1,"") -> 0.32761663 | R13: =T$10*$F13 -> -53623.839 | S13: -0.0262 | T13: =IFERROR(VLOOKUP($I13,RESUMO!$A$3:$M$200,3,FALSE),"") -> 71719.76 | U13: =IFERROR((T13*-1)/R13-1,"") -> 0.33746037 | V13: =X$10*$F13 -> -68807.577 | W13: -0.0262 | X13: =IFERROR(VLOOKUP($I13,RESUMO!$A$3:$M$200,4,FALSE),"") -> 81164.49 | Y13: =IFERROR((X13*-1)/V13-1,"") -> 0.17958651 | Z13: =AB$10*$F13 -> -60970.33 | AA13: -0.0262 | AB13: =IFERROR(VLOOKUP($I13,RESUMO!$A$3:$M$200,5,FALSE),"") -> 70210.77 | AC13: =IFERROR((AB13*-1)/Z13-1,"") -> 0.15155634 | AD13: -67147.067 | AE13: -0.0262 | AF13: =IFERROR(VLOOKUP($I13,RESUMO!$A$3:$M$200,6,FALSE),"") -> 0 | AG13: =IFERROR((AF13*-1)/AD13-1,"") -> -1 | AH13: -58103.516 | AI13: -0.0262 | AJ13: -58849.64 | AK13: -0.0262 | AL13: -70506.442 | AM13: -0.0262 | AN13: -78060.486 | AO13: -0.0262 | AP13: -78902.99 | AQ13: -0.0262 | AR13: -71750.576 | AS13: -0.0262 | AT13: -64359.537 | AU13: -0.0262 | AW13: -786000 | AX13: -0.0262 | AY13: -65500
B14: % | C14: 8 | D14: 9 | E14: % 8-9 de 2025 | F14: -0.02465 | H14: Letícia | I14: ICMS | J14: -61625 | K14: -0.02465 | L14: -49300 | M14: -0.02465 | N14: =P$10*$F14 -> -37118.808 | O14: -0.02465 | P14: =IFERROR(VLOOKUP($I14,RESUMO!$A$3:$M$200,2,FALSE),"") -> 60679.01 | Q14: =IFERROR((P14*-1)/N14-1,"") -> 0.63472412 | R14: =T$10*$F14 -> -50451.437 | S14: -0.02465 | T14: =IFERROR(VLOOKUP($I14,RESUMO!$A$3:$M$200,3,FALSE),"") -> 18975.32 | U14: =IFERROR((T14*-1)/R14-1,"") -> -0.6238894 | V14: =X$10*$F14 -> -64736.9 | W14: -0.02465 | X14: =IFERROR(VLOOKUP($I14,RESUMO!$A$3:$M$200,4,FALSE),"") -> 39057.06 | Y14: =IFERROR((X14*-1)/V14-1,"") -> -0.3966801 | Z14: =AB$10*$F14 -> -57363.307 | AA14: -0.02465 | AB14: =IFERROR(VLOOKUP($I14,RESUMO!$A$3:$M$200,5,FALSE),"") -> 24861.83 | AC14: =IFERROR((AB14*-1)/Z14-1,"") -> -0.56659001 | AD14: -63174.626 | AE14: -0.02465 | AF14: =IFERROR(VLOOKUP($I14,RESUMO!$A$3:$M$200,6,FALSE),"") -> 0 | AG14: =IFERROR((AF14*-1)/AD14-1,"") -> -1 | AH14: -54666.095 | AI14: -0.02465 | AJ14: -55368.077 | AK14: -0.02465 | AL14: -66335.259 | AM14: -0.02465 | AN14: -73442.403 | AO14: -0.02465 | AP14: -74235.065 | AQ14: -0.02465 | AR14: -67505.79 | AS14: -0.02465 | AT14: -60552.007 | AU14: -0.02465 | AW14: -739500 | AX14: -0.02465 | AY14: -61625
B15: % | C15: 8 | D15: 9 | E15: % 8-9 de 2025 | F15: -0.00275 | H15: Letícia | I15: PIS | J15: -6875 | K15: -0.00275 | L15: -5500 | M15: -0.00275 | N15: =P$10*$F15 -> -4141.0434 | O15: -0.00275 | P15: =IFERROR(VLOOKUP($I15,RESUMO!$A$3:$M$200,2,FALSE),"") -> 0 | Q15: =IFERROR((P15*-1)/N15-1,"") -> -1 | R15: =T$10*$F15 -> -5628.4564 | S15: -0.00275 | T15: =IFERROR(VLOOKUP($I15,RESUMO!$A$3:$M$200,3,FALSE),"") -> 496.96 | U15: =IFERROR((T15*-1)/R15-1,"") -> -0.91170581 | V15: =X$10*$F15 -> -7222.1693 | W15: -0.00275 | X15: =IFERROR(VLOOKUP($I15,RESUMO!$A$3:$M$200,4,FALSE),"") -> 3431.3 | Y15: =IFERROR((X15*-1)/V15-1,"") -> -0.52489344 | Z15: =AB$10*$F15 -> -6399.5575 | AA15: -0.00275 | AB15: =IFERROR(VLOOKUP($I15,RESUMO!$A$3:$M$200,5,FALSE),"") -> 2462.42 | AC15: =IFERROR((AB15*-1)/Z15-1,"") -> -0.61522027 | AD15: -7047.8791 | AE15: -0.00275 | AF15: =IFERROR(VLOOKUP($I15,RESUMO!$A$3:$M$200,6,FALSE),"") -> 0 | AG15: =IFERROR((AF15*-1)/AD15-1,"") -> -1 | AH15: -6098.6515 | AI15: -0.00275 | AJ15: -6176.966 | AK15: -0.00275 | AL15: -7400.4853 | AM15: -0.00275 | AN15: -8193.3716 | AO15: -0.00275 | AP15: -8281.8024 | AQ15: -0.00275 | AR15: -7531.0719 | AS15: -0.00275 | AT15: -6755.2949 | AU15: -0.00275 | AW15: -82500 | AX15: -0.00275 | AY15: -6875
B16: % | C16: 8 | D16: 9 | E16: % 8-9 de 2025 | F16: -0.0106 | H16: Letícia | I16: IPI | J16: -26500 | K16: -0.0106 | L16: -21200 | M16: -0.0106 | N16: =P$10*$F16 -> -15961.84 | O16: -0.0106 | P16: =IFERROR(VLOOKUP($I16,RESUMO!$A$3:$M$200,2,FALSE),"") -> 15874.39 | Q16: =IFERROR((P16*-1)/N16-1,"") -> -0.0054787034 | R16: =T$10*$F16 -> -21695.141 | S16: -0.0106 | T16: =IFERROR(VLOOKUP($I16,RESUMO!$A$3:$M$200,3,FALSE),"") -> 14761.73 | U16: =IFERROR((T16*-1)/R16-1,"") -> -0.31958359 | V16: =X$10*$F16 -> -27838.18 | W16: -0.0106 | X16: =IFERROR(VLOOKUP($I16,RESUMO!$A$3:$M$200,4,FALSE),"") -> 22197.7 | Y16: =IFERROR((X16*-1)/V16-1,"") -> -0.2026167 | Z16: =AB$10*$F16 -> -24667.385 | AA16: -0.0106 | AB16: =IFERROR(VLOOKUP($I16,RESUMO!$A$3:$M$200,5,FALSE),"") -> 20723.31 | AC16: =IFERROR((AB16*-1)/Z16-1,"") -> -0.15989029 | AD16: -27166.371 | AE16: -0.0106 | AF16: =IFERROR(VLOOKUP($I16,RESUMO!$A$3:$M$200,6,FALSE),"") -> 0 | AG16: =IFERROR((AF16*-1)/AD16-1,"") -> -1 | AH16: -23507.53 | AI16: -0.0106 | AJ16: -23809.396 | AK16: -0.0106 | AL16: -28525.507 | AM16: -0.0106 | AN16: -31581.723 | AO16: -0.0106 | AP16: -31922.584 | AQ16: -0.0106 | AR16: -29028.859 | AS16: -0.0106 | AT16: -26038.591 | AU16: -0.0106 | AW16: -318000 | AX16: -0.0106 | AY16: -26500
B17: % | C17: 8 | D17: 9 | E17: % 8-9 de 2025 | F17: -0.01275 | H17: Letícia | I17: COFINS | J17: -31875 | K17: -0.01275 | L17: -25500 | M17: -0.01275 | N17: =P$10*$F17 -> -19199.383 | O17: -0.01275 | P17: =IFERROR(VLOOKUP($I17,RESUMO!$A$3:$M$200,2,FALSE),"") -> 0 | Q17: =IFERROR((P17*-1)/N17-1,"") -> -1 | R17: =T$10*$F17 -> -26095.571 | S17: -0.01275 | T17: =IFERROR(VLOOKUP($I17,RESUMO!$A$3:$M$200,3,FALSE),"") -> 2460.61 | U17: =IFERROR((T17*-1)/R17-1,"") -> -0.90570775 | V17: =X$10*$F17 -> -33484.603 | W17: -0.01275 | X17: =IFERROR(VLOOKUP($I17,RESUMO!$A$3:$M$200,4,FALSE),"") -> 15906.25 | Y17: =IFERROR((X17*-1)/V17-1,"") -> -0.52496824 | Z17: =AB$10*$F17 -> -29670.676 | AA17: -0.01275 | AB17: =IFERROR(VLOOKUP($I17,RESUMO!$A$3:$M$200,5,FALSE),"") -> 11442.92 | AC17: =IFERROR((AB17*-1)/Z17-1,"") -> -0.61433571 | AD17: -32676.531 | AE17: -0.01275 | AF17: =IFERROR(VLOOKUP($I17,RESUMO!$A$3:$M$200,6,FALSE),"") -> 0 | AG17: =IFERROR((AF17*-1)/AD17-1,"") -> -1 | AH17: -28275.566 | AI17: -0.01275 | AJ17: -28638.66 | AK17: -0.01275 | AL17: -34311.341 | AM17: -0.01275 | AN17: -37987.45 | AO17: -0.01275 | AP17: -38397.447 | AQ17: -0.01275 | AR17: -34916.788 | AS17: -0.01275 | AT17: -31320.004 | AU17: -0.01275 | AW17: -382500 | AX17: -0.01275 | AY17: -31875
B18: % | C18: 8 | D18: 9 | E18: % 8-9 de 2025 | F18: -0.00085 | H18: Letícia | I18: Outros Impostos | J18: -2125 | K18: -0.00085 | L18: -1700 | M18: -0.00085 | N18: =P$10*$F18 -> -1279.9589 | O18: -0.00085 | P18: =IFERROR(VLOOKUP($I18,RESUMO!$A$3:$M$200,2,FALSE),"") -> 1443.62 | Q18: =IFERROR((P18*-1)/N18-1,"") -> 0.12786435 | R18: =T$10*$F18 -> -1739.7047 | S18: -0.00085 | T18: =IFERROR(VLOOKUP($I18,RESUMO!$A$3:$M$200,3,FALSE),"") -> 1490.09 | U18: =IFERROR((T18*-1)/R18-1,"") -> -0.14348108 | V18: =X$10*$F18 -> -2232.3069 | W18: -0.00085 | X18: =IFERROR(VLOOKUP($I18,RESUMO!$A$3:$M$200,4,FALSE),"") -> 1921.23 | Y18: =IFERROR((X18*-1)/V18-1,"") -> -0.13935221 | Z18: =AB$10*$F18 -> -1978.0451 | AA18: -0.00085 | AB18: =IFERROR(VLOOKUP($I18,RESUMO!$A$3:$M$200,5,FALSE),"") -> 4716.69 | AC18: =IFERROR((AB18*-1)/Z18-1,"") -> 1.384521 | AD18: -2178.4354 | AE18: -0.00085 | AF18: =IFERROR(VLOOKUP($I18,RESUMO!$A$3:$M$200,6,FALSE),"") -> 0 | AG18: =IFERROR((AF18*-1)/AD18-1,"") -> -1 | AH18: -1885.0377 | AI18: -0.00085 | AJ18: -1909.244 | AK18: -0.00085 | AL18: -2287.4227 | AM18: -0.00085 | AN18: -2532.4967 | AO18: -0.00085 | AP18: -2559.8298 | AQ18: -0.00085 | AR18: -2327.7859 | AS18: -0.00085 | AT18: -2088.0003 | AU18: -0.00085 | AW18: -25500 | AX18: -0.00085 | AY18: -2125
B19: % | C19: 8 | D19: 9 | E19: % 8-9 de 2025 | F19: -0.00085 | H19: Letícia | I19: Impostos a recolher | J19: -2125 | K19: -0.00085 | L19: -1700 | M19: -0.00085 | N19: 0 | O19: 0 | P19: =IFERROR(VLOOKUP($I19,RESUMO!$A$3:$M$200,2,FALSE),"") -> 5659.96 | Q19: =IFERROR((P19*-1)/N19-1,"") | R19: 0 | S19: -0.00085 | T19: =IFERROR(VLOOKUP($I19,RESUMO!$A$3:$M$200,3,FALSE),"") -> 5659.96 | U19: =IFERROR((T19*-1)/R19-1,"") | V19: 0 | W19: -0.00085 | X19: =IFERROR(VLOOKUP($I19,RESUMO!$A$3:$M$200,4,FALSE),"") -> 5659.96 | Y19: =IFERROR((X19*-1)/V19-1,"") | Z19: 0 | AA19: -0.00085 | AB19: =IFERROR(VLOOKUP($I19,RESUMO!$A$3:$M$200,5,FALSE),"") -> 5659.96 | AC19: =IFERROR((AB19*-1)/Z19-1,"") | AD19: 0 | AE19: -0.00085 | AF19: =IFERROR(VLOOKUP($I19,RESUMO!$A$3:$M$200,6,FALSE),"") -> 0 | AG19: =IFERROR((AF19*-1)/AD19-1,"") | AH19: -1885.0377 | AI19: -0.00085 | AJ19: 0 | AK19: -0.00085 | AL19: 0 | AM19: -0.00085 | AN19: 0 | AO19: -0.00085 | AP19: 0 | AQ19: -0.00085 | AR19: 0 | AS19: -0.00085 | AT19: 0 | AU19: -0.00085 | AW19: 0 | AX19: -0.00085 | AY19: -2125
I21: Receita Líquida | J21: 2305500 | K21: 0.9222 | L21: 1844400 | M21: 0.9222 | N21: 1497142.8 | O21: 0.9222 | P21: =P10-P12 -> 1369798.7 | Q21: =P21/N21-1 -> -0.08505805 | R21: 2052806.1 | S21: 0.9222 | T21: =T10-T12 -> 1931147 | U21: =T21/R21-1 -> -0.059264801 | V21: 2582555.4 | W21: 0.9222 | X21: =X10-X12 -> 2456905.4 | Y21: =X21/V21-1 -> -0.048653344 | Z21: 2255986.9 | AA21: 0.9222 | AB21: =AB10-AB12 -> 2187033.9 | AC21: =AB21/Z21-1 -> -0.030564449 | AD21: 2363474.2 | AE21: 0.9222 | AF21: =AF10-AF12 -> 430572.21 | AG21: =AF21/AD21-1 -> -0.81782234 | AH21: 2045155.1 | AI21: 0.9222 | AJ21: 2071417.5 | AK21: 0.9222 | AL21: 2481719.1 | AM21: 0.9222 | AN21: 2747609.9 | AO21: 0.9222 | AP21: 2777264.8 | AQ21: 0.9222 | AR21: 2525510.7 | AS21: 0.9222 | AT21: 2265357.5 | AU21: 0.9222 | AW21: 27666000 | AX21: 0.9222 | AY21: 2305500
I23: Custo | J23: -1407557 | K23: -0.56302279 | L23: -1214782 | M23: -0.60739099 | N23: =N24+N32+N46 -> -1024256.3 | O23: -0.65884626 | P23: =P24+P32+P46 -> 958701.04 | Q23: =IFERROR((P23*-1)/N23-1,"") -> -0.064002764 | R23: =R24+R32+R46 -> -1232791.6 | S23: -0.58486912 | T23: =T24+T32+T46 -> 1278370.6 | U23: =IFERROR((T23*-1)/R23-1,"") -> 0.036972168 | V23: =V24+V32+V46 -> -1456230.1 | W23: -0.54398359 | X23: =X24+X32+X46 -> 1479833.6 | Y23: =IFERROR((X23*-1)/V23-1,"") -> 0.016208596 | Z23: -1386856.7 | AA23: -0.56691786 | AB23: =AB24+AB32+AB46 -> 1173956.9 | AC23: =IFERROR((AB23*-1)/Z23-1,"") -> -0.15351252 | AD23: -1455440.7 | AE23: -0.56789594 | AF23: =AF24+AF32+AF46 -> 41622.25 | AG23: =IFERROR((AF23*-1)/AD23-1,"") -> -0.9714023 | AH23: -1322359 | AI23: -0.59627726 | AJ23: -1333338.7 | AK23: -0.59360556 | AL23: -1504876.1 | AM23: -0.55920782 | AN23: -1616038.7 | AO23: -0.54240266 | AP23: -1628436.7 | AQ23: -0.54072783 | AR23: -1523184.3 | AS23: -0.55619664 | AT23: -1414420.4 | AU23: -0.57579367 | AW23: -17079852 | AX23: -0.56932841 | AY23: -1423321
I24: CPV | J24: -963875 | K24: -0.38555 | L24: -771100 | M24: -0.38555 | N24: =SUM(N25:N31) -> -580574.29 | O24: -0.38555 | P24: =SUM(P25:P31) -> 572872.95 | Q24: =IFERROR((P24*-1)/N24-1,"") -> -0.01326504 | R24: =SUM(R25:R31) -> -789109.59 | S24: -0.38555 | T24: =SUM(T25:T31) -> 852739.33 | U24: =IFERROR((T24*-1)/R24-1,"") -> 0.080634856 | V24: =SUM(V25:V31) -> -1012548.1 | W24: -0.38555 | X24: =SUM(X25:X31) -> 1039300.8 | Y24: =IFERROR((X24*-1)/V24-1,"") -> 0.026421111 | Z24: =SUM(Z25:Z31) -> -897217.97 | AA24: -0.38555 | AB24: =SUM(AB25:AB31) -> 851006.53 | AC24: =IFERROR((AB24*-1)/Z24-1,"") -> -0.05150525 | AD24: -988112.66 | AE24: -0.38555 | AF24: =SUM(AF25:AF31) -> 2977.13 | AG24: =IFERROR((AF24*-1)/AD24-1,"") -> -0.99698705 | AH24: -855030.95 | AI24: -0.38555 | AJ24: -866010.63 | AK24: -0.38555 | AL24: -1037548 | AM24: -0.38555 | AN24: -1148710.7 | AO24: -0.38555 | AP24: -1161108.7 | AQ24: -0.38555 | AR24: -1055856.3 | AS24: -0.38555 | AT24: -947092.35 | AU24: -0.38555 | AW24: -11566500 | AX24: -0.38555 | AY24: -963875
B25: % | C25: 2 | D25: 9 | E25: % 2-9 de 2025 | F25: -0.08275 | H25: Mylena | I25: Entrada de Compras | J25: -206875 | K25: -0.08275 | L25: -165500 | M25: -0.08275 | N25: =P$10*$F25 -> -124607.76 | O25: -0.08275 | P25: 561916.11 | Q25: =IFERROR((P25*-1)/N25-1,"") -> 3.5094792 | R25: =T$10*$F25 -> -169365.37 | S25: -0.08275 | T25: 830151.62 | U25: =IFERROR((T25*-1)/R25-1,"") -> 3.9015428 | V25: =X$10*$F25 -> -217321.64 | W25: -0.08275 | X25: 1009819.9 | Y25: =IFERROR((X25*-1)/V25-1,"") -> 3.6466605 | Z25: =AB$10*$F25 -> -192568.5 | AA25: -0.08275 | AB25: 833834.01 | AC25: =IFERROR((AB25*-1)/Z25-1,"") -> 3.3300643 | AD25: -212077.09 | AE25: -0.08275 | AF25: =IFERROR(VLOOKUP($I25,RESUMO!$A$3:$M$200,6,FALSE),"") | AG25: =IFERROR((AF25*-1)/AD25-1,"") | AH25: -183513.97 | AI25: -0.08275 | AJ25: -185870.52 | AK25: -0.08275 | AL25: -222687.33 | AM25: -0.08275 | AN25: -246546 | AO25: -0.08275 | AP25: -249206.96 | AQ25: -0.08275 | AR25: -226616.8 | AS25: -0.08275 | AT25: -203272.97 | AU25: -0.08275 | AW25: -2482500 | AX25: -0.08275 | AY25: -206875
B26: % | C26: 2 | D26: 9 | E26: % 2-9 de 2025 | F26: 0 | H26: Mylena | I26: Compras | J26: -206875 | K26: -0.08275 | L26: -165500 | M26: -0.08275 | N26: =P$10*$F26 -> 0 | O26: 0 | P26: =IFERROR(VLOOKUP($I26,RESUMO!$A$3:$M$200,2,FALSE),"") -> 564 | Q26: =IFERROR((P26*-1)/N26-1,"") | R26: =T$10*$F26 -> 0 | S26: 0 | T26: =IFERROR(VLOOKUP($I26,RESUMO!$A$3:$M$200,3,FALSE),"") -> 987.68 | U26: =IFERROR((T26*-1)/R26-1,"") | V26: =X$10*$F26 -> 0 | W26: 0 | X26: =IFERROR(VLOOKUP($I26,RESUMO!$A$3:$M$200,4,FALSE),"") -> 1534.3 | Y26: =IFERROR((X26*-1)/V26-1,"") | Z26: =AB$10*$F26 -> 0 | AA26: 0 | AB26: =IFERROR(VLOOKUP($I26,RESUMO!$A$3:$M$200,5,FALSE),"") -> 9.5 | AC26: =IFERROR((AB26*-1)/Z26-1,"") | AD26: 0 | AE26: 0 | AF26: =IFERROR(VLOOKUP($I26,RESUMO!$A$3:$M$200,6,FALSE),"") -> 0 | AG26: =IFERROR((AF26*-1)/AD26-1,"") | AH26: 0 | AI26: 0 | AJ26: 0 | AK26: 0 | AL26: 0 | AM26: 0 | AN26: 0 | AO26: 0 | AP26: 0 | AQ26: 0 | AR26: 0 | AS26: 0 | AT26: 0 | AU26: 0 | AW26: -2482500 | AX26: -0.08275 | AY26: -206875
B27: % | C27: 2 | D27: 9 | E27: % 2-9 de 2025 | F27: -0.1049125 | H27: Mylena | I27: Compras - Espuma | J27: -262281.25 | K27: -0.1049125 | L27: -209825 | M27: -0.1049125 | N27: =P$10*$F27 -> -157980.81 | O27: -0.1049125 | P27: =IFERROR(VLOOKUP($I27,RESUMO!$A$3:$M$200,2,FALSE),"") | Q27: =IFERROR((P27*-1)/N27-1,"") | R27: =T$10*$F27 -> -214725.61 | S27: -0.1049125 | T27: =IFERROR(VLOOKUP($I27,RESUMO!$A$3:$M$200,3,FALSE),"") | U27: =IFERROR((T27*-1)/R27-1,"") | V27: =X$10*$F27 -> -275525.76 | W27: -0.1049125 | X27: =IFERROR(VLOOKUP($I27,RESUMO!$A$3:$M$200,4,FALSE),"") | Y27: =IFERROR((X27*-1)/V27-1,"") | Z27: =AB$10*$F27 -> -244143.12 | AA27: -0.1049125 | AB27: =IFERROR(VLOOKUP($I27,RESUMO!$A$3:$M$200,5,FALSE),"") | AC27: =IFERROR((AB27*-1)/Z27-1,"") | AD27: -268876.59 | AE27: -0.1049125 | AF27: =IFERROR(VLOOKUP($I27,RESUMO!$A$3:$M$200,6,FALSE),"") | AG27: =IFERROR((AF27*-1)/AD27-1,"") | AH27: -232663.56 | AI27: -0.1049125 | AJ27: -235651.25 | AK27: -0.1049125 | AL27: -282328.52 | AM27: -0.1049125 | AN27: -312577.13 | AO27: -0.1049125 | AP27: -315950.76 | AQ27: -0.1049125 | AR27: -287310.39 | AS27: -0.1049125 | AT27: -257714.5 | AU27: -0.1049125 | AW27: -3147375 | AX27: -0.1049125 | AY27: -262281.25
B28: % | C28: 2 | D28: 9 | E28: % 2-9 de 2025 | F28: -0.074375 | H28: Mylena | I28: Compras - Tecido | J28: -185937.5 | K28: -0.074375 | L28: -148750 | M28: -0.074375 | N28: =P$10*$F28 -> -111996.4 | O28: -0.074375 | P28: =IFERROR(VLOOKUP($I28,RESUMO!$A$3:$M$200,2,FALSE),"") | Q28: =IFERROR((P28*-1)/N28-1,"") | R28: =T$10*$F28 -> -152224.16 | S28: -0.074375 | T28: =IFERROR(VLOOKUP($I28,RESUMO!$A$3:$M$200,3,FALSE),"") | U28: =IFERROR((T28*-1)/R28-1,"") | V28: =X$10*$F28 -> -195326.85 | W28: -0.074375 | X28: =IFERROR(VLOOKUP($I28,RESUMO!$A$3:$M$200,4,FALSE),"") | Y28: =IFERROR((X28*-1)/V28-1,"") | Z28: =AB$10*$F28 -> -173078.94 | AA28: -0.074375 | AB28: =IFERROR(VLOOKUP($I28,RESUMO!$A$3:$M$200,5,FALSE),"") | AC28: =IFERROR((AB28*-1)/Z28-1,"") | AD28: -190613.1 | AE28: -0.074375 | AF28: =IFERROR(VLOOKUP($I28,RESUMO!$A$3:$M$200,6,FALSE),"") | AG28: =IFERROR((AF28*-1)/AD28-1,"") | AH28: -164940.8 | AI28: -0.074375 | AJ28: -167058.85 | AK28: -0.074375 | AL28: -200149.49 | AM28: -0.074375 | AN28: -221593.46 | AO28: -0.074375 | AP28: -223985.11 | AQ28: -0.074375 | AR28: -203681.26 | AS28: -0.074375 | AT28: -182700.02 | AU28: -0.074375 | AW28: -2231250 | AX28: -0.074375 | AY28: -185937.5
B29: % | C29: 2 | D29: 9 | E29: % 2-9 de 2025 | F29: -0.0567375 | H29: Mylena | I29: Compras - Madeira | J29: -141843.75 | K29: -0.0567375 | L29: -113475 | M29: -0.0567375 | N29: =P$10*$F29 -> -85437.255 | O29: -0.0567375 | P29: =IFERROR(VLOOKUP($I29,RESUMO!$A$3:$M$200,2,FALSE),"") | Q29: =IFERROR((P29*-1)/N29-1,"") | R29: =T$10*$F29 -> -116125.29 | S29: -0.0567375 | T29: =IFERROR(VLOOKUP($I29,RESUMO!$A$3:$M$200,3,FALSE),"") | U29: =IFERROR((T29*-1)/R29-1,"") | V29: =X$10*$F29 -> -149006.48 | W29: -0.0567375 | X29: =IFERROR(VLOOKUP($I29,RESUMO!$A$3:$M$200,4,FALSE),"") | Y29: =IFERROR((X29*-1)/V29-1,"") | Z29: =AB$10*$F29 -> -132034.51 | AA29: -0.0567375 | AB29: =IFERROR(VLOOKUP($I29,RESUMO!$A$3:$M$200,5,FALSE),"") | AC29: =IFERROR((AB29*-1)/Z29-1,"") | AD29: -145410.56 | AE29: -0.0567375 | AF29: =IFERROR(VLOOKUP($I29,RESUMO!$A$3:$M$200,6,FALSE),"") | AG29: =IFERROR((AF29*-1)/AD29-1,"") | AH29: -125826.27 | AI29: -0.0567375 | AJ29: -127442.04 | AK29: -0.0567375 | AL29: -152685.47 | AM29: -0.0567375 | AN29: -169044.15 | AO29: -0.0567375 | AP29: -170868.64 | AQ29: -0.0567375 | AR29: -155379.71 | AS29: -0.0567375 | AT29: -139374.02 | AU29: -0.0567375 | AW29: -1702125 | AX29: -0.0567375 | AY29: -141843.75
B30: % | C30: 2 | D30: 9 | E30: % 2-9 de 2025 | F30: -0.06165 | H30: Mylena | I30: Compras - Pés/Mecanismos/Bases | J30: -154125 | K30: -0.06165 | L30: -123300 | M30: -0.06165 | N30: =P$10*$F30 -> -92834.665 | O30: -0.06165 | P30: =IFERROR(VLOOKUP($I30,RESUMO!$A$3:$M$200,2,FALSE),"") -> 1 | Q30: =IFERROR((P30*-1)/N30-1,"") -> -0.99998923 | R30: =T$10*$F30 -> -126179.76 | S30: -0.06165 | T30: =IFERROR(VLOOKUP($I30,RESUMO!$A$3:$M$200,3,FALSE),"") -> 2516.68 | U30: =IFERROR((T30*-1)/R30-1,"") -> -0.9800548 | V30: =X$10*$F30 -> -161907.91 | W30: -0.06165 | X30: =IFERROR(VLOOKUP($I30,RESUMO!$A$3:$M$200,4,FALSE),"") -> 12217.75 | Y30: =IFERROR((X30*-1)/V30-1,"") -> -0.92453889 | Z30: =AB$10*$F30 -> -143466.44 | AA30: -0.06165 | AB30: =IFERROR(VLOOKUP($I30,RESUMO!$A$3:$M$200,5,FALSE),"") -> 962.38 | AC30: =IFERROR((AB30*-1)/Z30-1,"") -> -0.99329195 | AD30: -158000.64 | AE30: -0.06165 | AF30: =IFERROR(VLOOKUP($I30,RESUMO!$A$3:$M$200,6,FALSE),"") -> 67.11 | AG30: =IFERROR((AF30*-1)/AD30-1,"") -> -0.99957525 | AH30: -136720.68 | AI30: -0.06165 | AJ30: -138476.35 | AK30: -0.06165 | AL30: -165905.43 | AM30: -0.06165 | AN30: -183680.49 | AO30: -0.06165 | AP30: -185662.95 | AQ30: -0.06165 | AR30: -168832.94 | AS30: -0.06165 | AT30: -151441.43 | AU30: -0.06165 | AW30: -1849500 | AX30: -0.06165 | AY30: -154125
B31: % | C31: 2 | D31: 9 | E31: % 2-9 de 2025 | F31: -0.005125 | H31: Mylena | I31: Frete sobre compras | J31: -12812.5 | K31: -0.005125 | L31: -10250 | M31: -0.005125 | N31: =P$10*$F31 -> -7717.3991 | O31: -0.005125 | P31: =IFERROR(VLOOKUP($I31,RESUMO!$A$3:$M$200,2,FALSE),"") -> 10391.84 | Q31: =IFERROR((P31*-1)/N31-1,"") -> 0.34654691 | R31: =T$10*$F31 -> -10489.396 | S31: -0.005125 | T31: =IFERROR(VLOOKUP($I31,RESUMO!$A$3:$M$200,3,FALSE),"") -> 19083.35 | U31: =IFERROR((T31*-1)/R31-1,"") -> 0.81929921 | V31: =X$10*$F31 -> -13459.497 | W31: -0.005125 | X31: =IFERROR(VLOOKUP($I31,RESUMO!$A$3:$M$200,4,FALSE),"") -> 15728.86 | Y31: =IFERROR((X31*-1)/V31-1,"") -> 0.16860678 | Z31: =AB$10*$F31 -> -11926.448 | AA31: -0.005125 | AB31: =IFERROR(VLOOKUP($I31,RESUMO!$A$3:$M$200,5,FALSE),"") -> 16200.64 | AC31: =IFERROR((AB31*-1)/Z31-1,"") -> 0.35837928 | AD31: -13134.684 | AE31: -0.005125 | AF31: =IFERROR(VLOOKUP($I31,RESUMO!$A$3:$M$200,6,FALSE),"") -> 2910.02 | AG31: =IFERROR((AF31*-1)/AD31-1,"") -> -0.77844766 | AH31: -11365.669 | AI31: -0.005125 | AJ31: -11511.618 | AK31: -0.005125 | AL31: -13791.814 | AM31: -0.005125 | AN31: -15269.465 | AO31: -0.005125 | AP31: -15434.268 | AQ31: -0.005125 | AR31: -14035.179 | AS31: -0.005125 | AT31: -12589.413 | AU31: -0.005125 | AW31: -153750 | AX31: -0.005125 | AY31: -12812.5
I32: Custos Diretos | J32: -349495.63 | K32: -0.13979825 | L32: -349495.63 | M32: -0.17474782 | N32: -349495.63 | O32: -0.21527998 | P32: =SUM(P33:P45) -> 298438.85 | Q32: =(P32*-1)/N32-1 -> -0.14608704 | R32: -349495.63 | S32: -0.15700697 | T32: =SUM(T33:T45) -> 359850.92 | U32: =(T32*-1)/R32-1 -> 0.029629237 | V32: -349495.63 | W32: -0.12480076 | X32: =SUM(X33:X45) -> 333045.58 | Y32: =(X32*-1)/V32-1 -> -0.047067973 | Z32: -349495.63 | AA32: -0.14286646 | AB32: =SUM(AB33:AB45) -> 255313.36 | AC32: =(AB32*-1)/Z32-1 -> -0.26948054 | AD32: -369175.1 | AE32: -0.14404781 | AF32: =SUM(AF33:AF45) -> 21727.68 | AG32: =(AF32*-1)/AD32-1 -> -0.94114533 | AH32: -369175.1 | AI32: -0.1664682 | AJ32: -369175.1 | AK32: -0.16435764 | AL32: -369175.1 | AM32: -0.13718445 | AN32: -369175.1 | AO32: -0.12390888 | AP32: -369175.1 | AQ32: -0.12258582 | AR32: -369175.1 | AS32: -0.13480571 | AT32: -369175.1 | AU32: -0.15028678 | AW32: -4351383.3 | AX32: -0.14504611 | AY32: -362615.28
E33: Diretoria - 25.11.25 | F33: -4320 | H33: Rafael | I33: Energia Eletrica (Prod) | J33: -4320 | K33: -0.001728 | L33: -4320 | M33: -0.00216 | N33: -4320 | O33: -0.0026610047 | P33: =IFERROR(VLOOKUP($I33,RESUMO!$A$3:$M$200,2,FALSE),"") -> 4543.34 | Q33: =IFERROR((P33*-1)/N33-1,"") -> 0.051699074 | R33: -4320 | S33: -0.0019407113 | T33: =IFERROR(VLOOKUP($I33,RESUMO!$A$3:$M$200,3,FALSE),"") -> 6905.72 | U33: =IFERROR((T33*-1)/R33-1,"") -> 0.5985463 | V33: -4320 | W33: -0.0015426209 | X33: =IFERROR(VLOOKUP($I33,RESUMO!$A$3:$M$200,4,FALSE),"") -> 8155.15 | Y33: =IFERROR((X33*-1)/V33-1,"") -> 0.8877662 | Z33: -4320 | AA33: -0.0017659251 | AB33: =IFERROR(VLOOKUP($I33,RESUMO!$A$3:$M$200,5,FALSE),"") -> 8554.02 | AC33: =IFERROR((AB33*-1)/Z33-1,"") -> 0.98009722 | AD33: -4320 | AE33: -0.0016856135 | AF33: =IFERROR(VLOOKUP($I33,RESUMO!$A$3:$M$200,6,FALSE),"") -> 0 | AG33: =IFERROR((AF33*-1)/AD33-1,"") -> -1 | AH33: -4320 | AI33: -0.0019479716 | AJ33: -4320 | AK33: -0.0019232743 | AL33: -4320 | AM33: -0.0016053001 | AN33: -4320 | AO33: -0.0014499525 | AP33: -4320 | AQ33: -0.0014344704 | AR33: -4320 | AS33: -0.0015774647 | AT33: -4320 | AU33: -0.0017586205 | AW33: -51840 | AX33: -0.001728 | AY33: -4320
B34: $ | C34: 1 | D34: 9 | E34: $ 1-9 de 2025 | F34: -19046.924 | H34: Mylena | I34: Material de Expediente (Prod) | J34: -19046.924 | K34: -0.0076187698 | L34: -19046.924 | M34: -0.0095234622 | N34: -19046.924 | O34: -0.011732397 | P34: =IFERROR(VLOOKUP($I34,RESUMO!$A$3:$M$200,2,FALSE),"") -> 14950.47 | Q34: =IFERROR((P34*-1)/N34-1,"") -> -0.2150717 | R34: -19046.924 | S34: -0.0085566159 | T34: =IFERROR(VLOOKUP($I34,RESUMO!$A$3:$M$200,3,FALSE),"") -> 21105.59 | U34: =IFERROR((T34*-1)/R34-1,"") -> 0.10808388 | V34: -19046.924 | W34: -0.0068014316 | X34: =IFERROR(VLOOKUP($I34,RESUMO!$A$3:$M$200,4,FALSE),"") -> 9382.13 | Y34: =IFERROR((X34*-1)/V34-1,"") -> -0.50742021 | Z34: -19046.924 | AA34: -0.007785982 | AB34: =IFERROR(VLOOKUP($I34,RESUMO!$A$3:$M$200,5,FALSE),"") -> 16740.67 | AC34: =IFERROR((AB34*-1)/Z34-1,"") -> -0.12108277 | AD34: -19046.924 | AE34: -0.0074318871 | AF34: =IFERROR(VLOOKUP($I34,RESUMO!$A$3:$M$200,6,FALSE),"") -> 5750.17 | AG34: =IFERROR((AF34*-1)/AD34-1,"") -> -0.69810507 | AH34: -19046.924 | AI34: -0.0085886268 | AJ34: -19046.924 | AK34: -0.0084797362 | AL34: -19046.924 | AM34: -0.0070777847 | AN34: -19046.924 | AO34: -0.0063928557 | AP34: -19046.924 | AQ34: -0.0063245946 | AR34: -19046.924 | AS34: -0.0069550581 | AT34: -19046.924 | AU34: -0.0077537758 | AW34: -228563.09 | AX34: -0.0076187698 | AY34: -19046.924
E35: Diretoria - 25.11.25 | F35: -2194.03 | H35: Rafael | I35: EPIs/Uniformes (Prod) | J35: -2194.03 | K35: -0.000877612 | L35: -2194.03 | M35: -0.001097015 | N35: -2194.03 | O35: -0.0013514639 | P35: =IFERROR(VLOOKUP($I35,RESUMO!$A$3:$M$200,2,FALSE),"") -> 1899.2 | Q35: =IFERROR((P35*-1)/N35-1,"") -> -0.13437829 | R35: -2194.03 | S35: -0.00098564322 | T35: =IFERROR(VLOOKUP($I35,RESUMO!$A$3:$M$200,3,FALSE),"") -> 1694.16 | U35: =IFERROR((T35*-1)/R35-1,"") -> -0.22783189 | V35: -2194.03 | W35: -0.00078346218 | X35: =IFERROR(VLOOKUP($I35,RESUMO!$A$3:$M$200,4,FALSE),"") -> 0 | Y35: =IFERROR((X35*-1)/V35-1,"") -> -1 | Z35: -2194.03 | AA35: -0.00089687331 | AB35: =IFERROR(VLOOKUP($I35,RESUMO!$A$3:$M$200,5,FALSE),"") -> 1307.92 | AC35: =IFERROR((AB35*-1)/Z35-1,"") -> -0.40387324 | AD35: -2194.03 | AE35: -0.00085608484 | AF35: =IFERROR(VLOOKUP($I35,RESUMO!$A$3:$M$200,6,FALSE),"") -> 9103.6 | AG35: =IFERROR((AF35*-1)/AD35-1,"") -> 3.1492596 | AH35: -2194.03 | AI35: -0.00098933059 | AJ35: -2194.03 | AK35: -0.00097678739 | AL35: -2194.03 | AM35: -0.00081529551 | AN35: -2194.03 | AO35: -0.00073639801 | AP35: -2194.03 | AQ35: -0.00072853495 | AR35: -2194.03 | AS35: -0.00080115853 | AT35: -2194.03 | AU35: -0.00089316345 | AW35: -26328.36 | AX35: -0.000877612 | AY35: -2194.03
E36: Salarios e Ordenados MOD | F36: AUX | H36: Rafael | I36: Salarios e Ordenados MOD | J36: -208162.69 | K36: -0.083265075 | L36: -208162.69 | M36: -0.10408134 | N36: -208162.69 | O36: -0.12822266 | P36: =IFERROR(VLOOKUP($I36,RESUMO!$A$3:$M$200,2,FALSE),"") -> 185861.81 | Q36: =IFERROR((P36*-1)/N36-1,"") -> -0.10713196 | R36: -208162.69 | S36: -0.093514738 | T36: =IFERROR(VLOOKUP($I36,RESUMO!$A$3:$M$200,3,FALSE),"") -> 205896.33 | U36: =IFERROR((T36*-1)/R36-1,"") -> -0.01088743 | V36: -208162.69 | W36: -0.074332435 | X36: =IFERROR(VLOOKUP($I36,RESUMO!$A$3:$M$200,4,FALSE),"") -> 218151.71 | Y36: =IFERROR((X36*-1)/V36-1,"") -> 0.047986618 | Z36: -208162.69 | AA36: -0.085092527 | AB36: =IFERROR(VLOOKUP($I36,RESUMO!$A$3:$M$200,5,FALSE),"") -> 202715.75 | AC36: =IFERROR((AB36*-1)/Z36-1,"") -> -0.026166729 | AD36: -221693.26 | AE36: -0.086502117 | AF36: =IFERROR(VLOOKUP($I36,RESUMO!$A$3:$M$200,6,FALSE),"") -> 3820.7 | AG36: =IFERROR((AF36*-1)/AD36-1,"") -> -0.98276583 | AH36: -221693.26 | AI36: -0.099965782 | AJ36: -221693.26 | AK36: -0.098698369 | AL36: -221693.26 | AM36: -0.082380606 | AN36: -221693.26 | AO36: -0.074408498 | AP36: -221693.26 | AQ36: -0.073613984 | AR36: -221693.26 | AS36: -0.080952151 | AT36: -221693.26 | AU36: -0.090248683 | AW36: -2606196.8 | AX36: -0.086873228 | AY36: -217183.07
B37: $ | C37: 1 | D37: 9 | E37: $ 1-9 de 2025 | F37: -122.7 | H37: Rafael | I37: Horas Extras MOD | J37: -122.7 | K37: -4.908e-05 | L37: -122.7 | M37: -6.135e-05 | N37: -122.7 | O37: -7.5579925e-05 | P37: =IFERROR(VLOOKUP($I37,RESUMO!$A$3:$M$200,2,FALSE),"") | Q37: =IFERROR((P37*-1)/N37-1,"") | R37: -122.7 | S37: -5.5121591e-05 | T37: =IFERROR(VLOOKUP($I37,RESUMO!$A$3:$M$200,3,FALSE),"") | U37: =IFERROR((T37*-1)/R37-1,"") | V37: -122.7 | W37: -4.381472e-05 | X37: =IFERROR(VLOOKUP($I37,RESUMO!$A$3:$M$200,4,FALSE),"") | Y37: =IFERROR((X37*-1)/V37-1,"") | Z37: -122.7 | AA37: -5.0157179e-05 | AB37: =IFERROR(VLOOKUP($I37,RESUMO!$A$3:$M$200,5,FALSE),"") | AC37: =IFERROR((AB37*-1)/Z37-1,"") | AD37: -122.7 | AE37: -4.7876105e-05 | AF37: =IFERROR(VLOOKUP($I37,RESUMO!$A$3:$M$200,6,FALSE),"") | AG37: =IFERROR((AF37*-1)/AD37-1,"") | AH37: -122.7 | AI37: -5.5327804e-05 | AJ37: -122.7 | AK37: -5.4626333e-05 | AL37: -122.7 | AM37: -4.5594983e-05 | AN37: -122.7 | AO37: -4.118268e-05 | AP37: -122.7 | AQ37: -4.0742943e-05 | AR37: -122.7 | AS37: -4.4804379e-05 | AT37: -122.7 | AU37: -4.9949707e-05 | AW37: -1472.4 | AX37: -4.908e-05 | AY37: -122.7
E38: Provisão | F38: 0.083333333 | H38: Rafael | I38: 13° Salario MOD | J38: -17346.891 | K38: -0.0069387562 | L38: -17346.891 | M38: -0.0086734453 | N38: -17346.891 | O38: -0.010685222 | P38: =IFERROR(VLOOKUP($I38,RESUMO!$A$3:$M$200,2,FALSE),"") | Q38: =IFERROR((P38*-1)/N38-1,"") | R38: -17346.891 | S38: -0.0077928949 | T38: =IFERROR(VLOOKUP($I38,RESUMO!$A$3:$M$200,3,FALSE),"") | U38: =IFERROR((T38*-1)/R38-1,"") | V38: -17346.891 | W38: -0.0061943696 | X38: =IFERROR(VLOOKUP($I38,RESUMO!$A$3:$M$200,4,FALSE),"") | Y38: =IFERROR((X38*-1)/V38-1,"") | Z38: -17346.891 | AA38: -0.007091044 | AB38: =IFERROR(VLOOKUP($I38,RESUMO!$A$3:$M$200,5,FALSE),"") | AC38: =IFERROR((AB38*-1)/Z38-1,"") | AD38: -18474.438 | AE38: -0.0072085098 | AF38: =IFERROR(VLOOKUP($I38,RESUMO!$A$3:$M$200,6,FALSE),"") | AG38: =IFERROR((AF38*-1)/AD38-1,"") | AH38: -18474.438 | AI38: -0.0083304818 | AJ38: -18474.438 | AK38: -0.0082248641 | AL38: -18474.438 | AM38: -0.0068650505 | AN38: -18474.438 | AO38: -0.0062007081 | AP38: -18474.438 | AQ38: -0.0061344987 | AR38: -18474.438 | AS38: -0.0067460126 | AT38: -18474.438 | AU38: -0.0075207236 | AW38: -217183.07 | AX38: -0.0072394357 | AY38: -18098.589
B39: $ | C39: 1 | D39: 9 | E39: $ 1-9 de 2025 | F39: -7819.1 | H39: Rafael | I39: Gratificacoes MOD | J39: -7819.1 | K39: -0.00312764 | L39: -7819.1 | M39: -0.00390955 | N39: -7819.1 | O39: -0.0048163569 | P39: =IFERROR(VLOOKUP($I39,RESUMO!$A$3:$M$200,2,FALSE),"") -> 6816.55 | Q39: =IFERROR((P39*-1)/N39-1,"") -> -0.12821808 | R39: -7819.1 | S39: -0.0035126425 | T39: =IFERROR(VLOOKUP($I39,RESUMO!$A$3:$M$200,3,FALSE),"") -> 9992.25 | U39: =IFERROR((T39*-1)/R39-1,"") -> 0.27792841 | V39: -7819.1 | W39: -0.0027921082 | X39: =IFERROR(VLOOKUP($I39,RESUMO!$A$3:$M$200,4,FALSE),"") -> 8223.1 | Y39: =IFERROR((X39*-1)/V39-1,"") -> 0.051668351 | Z39: -7819.1 | AA39: -0.0031962836 | AB39: =IFERROR(VLOOKUP($I39,RESUMO!$A$3:$M$200,5,FALSE),"") -> 1988.1 | AC39: =IFERROR((AB39*-1)/Z39-1,"") -> -0.745738 | AD39: -7819.1 | AE39: -0.0030509214 | AF39: =IFERROR(VLOOKUP($I39,RESUMO!$A$3:$M$200,6,FALSE),"") -> 0 | AG39: =IFERROR((AF39*-1)/AD39-1,"") -> -1 | AH39: -7819.1 | AI39: -0.0035257835 | AJ39: -7819.1 | AK39: -0.003481082 | AL39: -7819.1 | AM39: -0.0029055561 | AN39: -7819.1 | AO39: -0.0026243806 | AP39: -7819.1 | AQ39: -0.0025963581 | AR39: -7819.1 | AS39: -0.0028551746 | AT39: -7819.1 | AU39: -0.0031830624 | AW39: -93829.2 | AX39: -0.00312764 | AY39: -7819.1
E40: Diretoria - 25.11.25 | F40: -10000 | H40: Rafael | I40: Rescisões MOD | J40: -10000 | K40: -0.004 | L40: -10000 | M40: -0.005 | N40: -10000 | O40: -0.0061597331 | P40: =IFERROR(VLOOKUP($I40,RESUMO!$A$3:$M$200,2,FALSE),"") -> 0 | Q40: =IFERROR((P40*-1)/N40-1,"") -> -1 | R40: -10000 | S40: -0.0044923872 | T40: =IFERROR(VLOOKUP($I40,RESUMO!$A$3:$M$200,3,FALSE),"") -> 30936.21 | U40: =IFERROR((T40*-1)/R40-1,"") -> 2.093621 | V40: -10000 | W40: -0.0035708818 | X40: =IFERROR(VLOOKUP($I40,RESUMO!$A$3:$M$200,4,FALSE),"") -> 394.44 | Y40: =IFERROR((X40*-1)/V40-1,"") -> -0.960556 | Z40: -10000 | AA40: -0.0040877896 | AB40: =IFERROR(VLOOKUP($I40,RESUMO!$A$3:$M$200,5,FALSE),"") -> 0 | AC40: =IFERROR((AB40*-1)/Z40-1,"") -> -1 | AD40: -10000 | AE40: -0.003901883 | AF40: =IFERROR(VLOOKUP($I40,RESUMO!$A$3:$M$200,6,FALSE),"") -> 1694.75 | AG40: =IFERROR((AF40*-1)/AD40-1,"") -> -0.830525 | AH40: -10000 | AI40: -0.0045091935 | AJ40: -10000 | AK40: -0.0044520239 | AL40: -10000 | AM40: -0.0037159725 | AN40: -10000 | AO40: -0.0033563716 | AP40: -10000 | AQ40: -0.0033205332 | AR40: -10000 | AS40: -0.0036515386 | AT40: -10000 | AU40: -0.0040708807 | AW40: -120000 | AX40: -0.004 | AY40: -10000
B41: $ | C41: 1 | D41: 9 | E41: $ 1-9 de 2025 | F41: -1291.6117 | H41: Rafael | I41: Assistência Médica MOD | J41: -1291.6117 | K41: -0.00051664467 | L41: -1291.6117 | M41: -0.00064580583 | N41: -1291.6117 | O41: -0.00079559832 | P41: =IFERROR(VLOOKUP($I41,RESUMO!$A$3:$M$200,2,FALSE),"") -> 808 | Q41: =IFERROR((P41*-1)/N41-1,"") -> -0.37442498 | R41: -1291.6117 | S41: -0.00058024197 | T41: =IFERROR(VLOOKUP($I41,RESUMO!$A$3:$M$200,3,FALSE),"") -> 570 | U41: =IFERROR((T41*-1)/R41-1,"") -> -0.55869089 | V41: -1291.6117 | W41: -0.00046121926 | X41: =IFERROR(VLOOKUP($I41,RESUMO!$A$3:$M$200,4,FALSE),"") -> 349.9 | Y41: =IFERROR((X41*-1)/V41-1,"") -> -0.72909814 | Z41: -1291.6117 | AA41: -0.00052798368 | AB41: =IFERROR(VLOOKUP($I41,RESUMO!$A$3:$M$200,5,FALSE),"") -> 420 | AC41: =IFERROR((AB41*-1)/Z41-1,"") -> -0.67482486 | AD41: -1291.6117 | AE41: -0.00050397176 | AF41: =IFERROR(VLOOKUP($I41,RESUMO!$A$3:$M$200,6,FALSE),"") -> 0 | AG41: =IFERROR((AF41*-1)/AD41-1,"") -> -1 | AH41: -1291.6117 | AI41: -0.0005824127 | AJ41: -1291.6117 | AK41: -0.0005750286 | AL41: -1291.6117 | AM41: -0.00047995934 | AN41: -1291.6117 | AO41: -0.00043351288 | AP41: -1291.6117 | AQ41: -0.00042888395 | AR41: -1291.6117 | AS41: -0.00047163699 | AT41: -1291.6117 | AU41: -0.0005257997 | AW41: -15499.34 | AX41: -0.00051664467 | AY41: -1291.6117
E42: Média + IPCA | F42: -1940.2017 | H42: Rafael | I42: Seguro de Vida MOD | J42: -1940.2017 | K42: -0.00077608067 | L42: -1940.2017 | M42: -0.00097010083 | N42: -1940.2017 | O42: -0.0011951124 | P42: =IFERROR(VLOOKUP($I42,RESUMO!$A$3:$M$200,2,FALSE),"") -> 1983.19 | Q42: =IFERROR((P42*-1)/N42-1,"") -> 0.022156631 | R42: -1940.2017 | S42: -0.00087161371 | T42: =IFERROR(VLOOKUP($I42,RESUMO!$A$3:$M$200,3,FALSE),"") -> 1883.98 | U42: =IFERROR((T42*-1)/R42-1,"") -> -0.028977228 | V42: -1940.2017 | W42: -0.00069282309 | X42: =IFERROR(VLOOKUP($I42,RESUMO!$A$3:$M$200,4,FALSE),"") -> 1980.53 | Y42: =IFERROR((X42*-1)/V42-1,"") -> 0.02078564 | Z42: -1940.2017 | AA42: -0.00079311363 | AB42: =IFERROR(VLOOKUP($I42,RESUMO!$A$3:$M$200,5,FALSE),"") -> 2040.6 | AC42: =IFERROR((AB42*-1)/Z42-1,"") -> 0.051746339 | AD42: -1940.2017 | AE42: -0.00075704399 | AF42: =IFERROR(VLOOKUP($I42,RESUMO!$A$3:$M$200,6,FALSE),"") -> 0 | AG42: =IFERROR((AF42*-1)/AD42-1,"") -> -1 | AH42: -1940.2017 | AI42: -0.00087487448 | AJ42: -1940.2017 | AK42: -0.00086378241 | AL42: -1940.2017 | AM42: -0.0007209736 | AN42: -1940.2017 | AO42: -0.00065120379 | AP42: -1940.2017 | AQ42: -0.00064425041 | AR42: -1940.2017 | AS42: -0.00070847214 | AT42: -1940.2017 | AU42: -0.00078983296 | AW42: -23282.42 | AX42: -0.00077608067 | AY42: -1940.2017
E43: Provisão | F43: 0.08 | H43: Rafael | I43: FGTS MOD | J43: -16653.015 | K43: -0.006661206 | L43: -16653.015 | M43: -0.0083265075 | N43: -16653.015 | O43: -0.010257813 | P43: =IFERROR(VLOOKUP($I43,RESUMO!$A$3:$M$200,2,FALSE),"") -> 34431.98 | Q43: =IFERROR((P43*-1)/N43-1,"") -> 1.0676124 | R43: -16653.015 | S43: -0.0074811791 | T43: =IFERROR(VLOOKUP($I43,RESUMO!$A$3:$M$200,3,FALSE),"") -> 32736.5 | U43: =IFERROR((T43*-1)/R43-1,"") -> 0.96580019 | V43: -16653.015 | W43: -0.0059465948 | X43: =IFERROR(VLOOKUP($I43,RESUMO!$A$3:$M$200,4,FALSE),"") -> 35869.64 | Y43: =IFERROR((X43*-1)/V43-1,"") -> 1.1539427 | Z43: -16653.015 | AA43: -0.0068074022 | AB43: =IFERROR(VLOOKUP($I43,RESUMO!$A$3:$M$200,5,FALSE),"") -> 0 | AC43: =IFERROR((AB43*-1)/Z43-1,"") -> -1 | AD43: -17735.461 | AE43: -0.0069201694 | AF43: =IFERROR(VLOOKUP($I43,RESUMO!$A$3:$M$200,6,FALSE),"") -> 0 | AG43: =IFERROR((AF43*-1)/AD43-1,"") -> -1 | AH43: -17735.461 | AI43: -0.0079972625 | AJ43: -17735.461 | AK43: -0.0078958695 | AL43: -17735.461 | AM43: -0.0065904485 | AN43: -17735.461 | AO43: -0.0059526798 | AP43: -17735.461 | AQ43: -0.0058891187 | AR43: -17735.461 | AS43: -0.0064761721 | AT43: -17735.461 | AU43: -0.0072198946 | AW43: -208495.75 | AX43: -0.0069498582 | AY43: -17374.646
E44: Provisão | F44: 0.18 | H44: Rafael | I44: INSS MOD | J44: -37469.284 | K44: -0.014987713 | L44: -37469.284 | M44: -0.018734642 | N44: -37469.284 | O44: -0.023080079 | P44: =IFERROR(VLOOKUP($I44,RESUMO!$A$3:$M$200,2,FALSE),"") -> 44369.08 | Q44: =IFERROR((P44*-1)/N44-1,"") -> 0.1841454 | R44: -37469.284 | S44: -0.016832653 | T44: =IFERROR(VLOOKUP($I44,RESUMO!$A$3:$M$200,3,FALSE),"") -> 42800.44 | U44: =IFERROR((T44*-1)/R44-1,"") -> 0.14228071 | V44: -37469.284 | W44: -0.013379838 | X44: =IFERROR(VLOOKUP($I44,RESUMO!$A$3:$M$200,4,FALSE),"") -> 44918.66 | Y44: =IFERROR((X44*-1)/V44-1,"") -> 0.19881289 | Z44: -37469.284 | AA44: -0.015316655 | AB44: =IFERROR(VLOOKUP($I44,RESUMO!$A$3:$M$200,5,FALSE),"") -> 0 | AC44: =IFERROR((AB44*-1)/Z44-1,"") -> -1 | AD44: -39904.787 | AE44: -0.015570381 | AF44: =IFERROR(VLOOKUP($I44,RESUMO!$A$3:$M$200,6,FALSE),"") -> 0 | AG44: =IFERROR((AF44*-1)/AD44-1,"") -> -1 | AH44: -39904.787 | AI44: -0.017993841 | AJ44: -39904.787 | AK44: -0.017765706 | AL44: -39904.787 | AM44: -0.014828509 | AN44: -39904.787 | AO44: -0.01339353 | AP44: -39904.787 | AQ44: -0.013250517 | AR44: -39904.787 | AS44: -0.014571387 | AT44: -39904.787 | AU44: -0.016244763 | AW44: -469115.43 | AX44: -0.015637181 | AY44: -39092.953
...

Sheet RESUMO
A3: Soma de Vlr Despesa | B3: Rótulos de Coluna
A4: Rótulos de Linha | B4: jan | C4: fev | D4: mar | E4: abr | F4: mai | G4: Total Geral
A5: 0 - TRIBUTOS | B5: 136035.24 | C5: 115564.43 | D5: 169337.99 | E5: 140077.9 | G5: 561015.56
A6: COFINS | C6: 2460.61 | D6: 15906.25 | E6: 11442.92 | G6: 29809.78
A7: ICMS | B7: 60679.01 | C7: 18975.32 | D7: 39057.06 | E7: 24861.83 | G7: 143573.22
A8: Impostos a recolher | B8: 5659.96 | C8: 5659.96 | D8: 5659.96 | E8: 5659.96 | G8: 22639.84
A9: IPI | B9: 15874.39 | C9: 14761.73 | D9: 22197.7 | E9: 20723.31 | G9: 73557.13
A10: Outros Impostos | B10: 1443.62 | C10: 1490.09 | D10: 1921.23 | E10: 4716.69 | G10: 9571.63
A11: PIS | C11: 496.96 | D11: 3431.3 | E11: 2462.42 | G11: 6390.68
A12: Simples Nacional | B12: 52378.26 | C12: 71719.76 | D12: 81164.49 | E12: 70210.77 | G12: 275473.28
A13: 1 - CPV | B13: 10956.84 | C13: 22587.71 | D13: 29480.91 | E13: 17172.52 | F13: 2977.13 | G13: 83175.11
A14: Compras | B14: 564 | C14: 987.68 | D14: 1534.3 | E14: 9.5 | G14: 3095.48
A15: Compras - Pés/Mecanismos/Bases | B15: 1 | C15: 2516.68 | D15: 12217.75 | E15: 962.38 | F15: 67.11 | G15: 15764.92
A16: Frete sobre Compras | B16: 10391.84 | C16: 19083.35 | D16: 15728.86 | E16: 16200.64 | F16: 2910.02 | G16: 64314.71
A17: 2 - CUSTOS DIRETOS | B17: 298438.85 | C17: 359850.92 | D17: 333045.58 | E17: 255313.36 | F17: 21727.68 | G17: 1268376.4
A18: Assistência Médica MOD | B18: 808 | C18: 570 | D18: 349.9 | E18: 420 | G18: 2147.9
A19: Energia Eletrica (Prod) | B19: 4543.34 | C19: 6905.72 | D19: 8155.15 | E19: 8554.02 | G19: 28158.23
A20: EPIs/Uniformes (Prod) | B20: 1899.2 | C20: 1694.16 | E20: 1307.92 | F20: 9103.6 | G20: 14004.88
A21: Férias MOD | B21: 2775.23 | C21: 5329.74 | D21: 5620.32 | E21: 21546.3 | F21: 1358.46 | G21: 36630.05
A22: FGTS MOD | B22: 34431.98 | C22: 32736.5 | D22: 35869.64 | G22: 103038.12
A23: Gratificacoes MOD | B23: 6816.55 | C23: 9992.25 | D23: 8223.1 | E23: 1988.1 | G23: 27020
A24: INSS MOD | B24: 44369.08 | C24: 42800.44 | D24: 44918.66 | G24: 132088.18
A25: Material de Expediente (Prod) | B25: 14950.47 | C25: 21105.59 | D25: 9382.13 | E25: 16740.67 | F25: 5750.17 | G25: 67929.03
A26: Rescisões MOD | C26: 30936.21 | D26: 394.44 | F26: 1694.75 | G26: 33025.4
A27: Salarios e Ordenados MOD | B27: 185861.81 | C27: 205896.33 | D27: 218151.71 | E27: 202715.75 | F27: 3820.7 | G27: 816446.3
A28: Seguro de Vida MOD | B28: 1983.19 | C28: 1883.98 | D28: 1980.53 | E28: 2040.6 | G28: 7888.3
A29: 3 - CUSTOS INDIRETOS | B29: 87389.24 | C29: 65780.3 | D29: 107667.2 | E29: 67636.97 | F29: 16917.44 | G29: 345391.15
A30: Assistência Médica CIF | E30: 225 | G30: 225
A31: Cursos e Treinamentos CIF | B31: 2934.94 | C31: 1387.7 | D31: 705.03 | G31: 5027.67
A32: Férias CIF | D32: 1458.08 | E32: 1316.22 | G32: 2774.3
A33: FGTS CIF | B33: 6497.95 | C33: 5251.66 | D33: 5035.68 | G33: 16785.29
A34: Gratificações CIF | B34: 3000.69 | C34: 2925.69 | D34: 1589.46 | E34: 1479.46 | G34: 8995.3
A35: Horas Extras CIF | B35: 230 | G35: 230
A36: INSS CIF | B36: 8026.61 | C36: 8297.76 | D36: 8006.02 | G36: 24330.39
A37: IPTU e Taxas Municipais CIF | E37: 2849.74 | G37: 2849.74
A38: Manutenção de Equipamentos (Prod) | B38: 2679.92 | C38: 9080.05 | D38: 50727.39 | E38: 6964.81 | F38: 1139.6 | G38: 70591.77
A39: Manutenção Predial CIF | B39: 22729.92 | C39: 3526.05 | D39: 6703.59 | E39: 8001.47 | F39: 889 | G39: 41850.03
A40: Material de Limpeza CIF | B40: 1649.3 | C40: 1675.48 | D40: 2109.7 | E40: 2093.6 | F40: 2112.39 | G40: 9640.47
A41: Medicina e Seguranca do Trabalho CIF | B41: 2316.15 | C41: 2405.31 | D41: 2405.31 | E41: 2405.31 | G41: 9532.08
A42: Medicina e Segurança do Trabalho MOD | D42: 180 | G42: 180
...

Sheet DESPESAS
A1: Cód. | B1: Emp | C1: Nro Doc. | D1: Dt. Entrada | E1: Fornecedor | F1: Vlr Despesa | G1: Plano de Contas | H1: Conta | I1: MÁQUINA2 | J1: CENTRO DE CUSTO | K1: SETOR | L1: TAG | M1: RESPONSÁVEL
A2: 53592 | B2: LAY | C2: 000005 | D2: 46052 | E2: CRIATIVE MOVEIS PLANEJADOS LTDA | F2: 564 | G2: 3.4.2.1 - Compras | H2: =VLOOKUP(DESPESAS[[#This Row],[Plano de Contas]],BASE!$B$3:$D$119,3,FALSE) -> Compras | I2: =IFERROR(VLOOKUP(DESPESAS[[#This Row],[Fornecedor]],Tabela2[],2,FALSE),"") | J2: =IFERROR(VLOOKUP(DESPESAS[[#This Row],[Plano de Contas]],BASE!$B$3:$F$119,4,FALSE),"") -> 1 - CPV | K2: =IFERROR(VLOOKUP(DESPESAS[[#This Row],[Plano de Contas]],BASE!$B$3:$H$119,5,FALSE),"") -> COMPRAS | L2: =IFERROR(VLOOKUP(DESPESAS[[#This Row],[Plano de Contas]],BASE!$B$3:$H$119,6,FALSE),"") -> 0 | M2: =VLOOKUP(DESPESAS[[#This Row],[Plano de Contas]],BASE!$B$3:$H$119,7,FALSE) -> MYLENA
A3: 53605 | B3: KAR | C3: 035688 | D3: 46053 | E3: METALURGICA CELINO LTDA | F3: 1 | G3: 3.4.2.6 - Compras - Pés/Mecanismos/Bases | H3: =VLOOKUP(DESPESAS[[#This Row],[Plano de Contas]],BASE!$B$3:$D$119,3,FALSE) -> Compras - Pés/Mecanismos/Bases | I3: =IFERROR(VLOOKUP(DESPESAS[[#This Row],[Fornecedor]],Tabela2[],2,FALSE),"") | J3: =IFERROR(VLOOKUP(DESPESAS[[#This Row],[Plano de Contas]],BASE!$B$3:$F$119,4,FALSE),"") -> 1 - CPV | K3: =IFERROR(VLOOKUP(DESPESAS[[#This Row],[Plano de Contas]],BASE!$B$3:$H$119,5,FALSE),"") -> COMPRAS | L3: =IFERROR(VLOOKUP(DESPESAS[[#This Row],[Plano de Contas]],BASE!$B$3:$H$119,6,FALSE),"") -> 0 | M3: =VLOOKUP(DESPESAS[[#This Row],[Plano de Contas]],BASE!$B$3:$H$119,7,FALSE) -> MYLENA
A4: 53632 | B4: KAR | C4: 019042 | D4: 46062 | E4: LINE DO BRASIL COMERCIO DE ATUADORES LINEARES LTDA | F4: 125.38 | G4: 3.4.2.6 - Compras - Pés/Mecanismos/Bases | H4: =VLOOKUP(DESPESAS[[#This Row],[Plano de Contas]],BASE!$B$3:$D$119,3,FALSE) -> Compras - Pés/Mecanismos/Bases | I4: =IFERROR(VLOOKUP(DESPESAS[[#This Row],[Fornecedor]],Tabela2[],2,FALSE),"") | J4: =IFERROR(VLOOKUP(DESPESAS[[#This Row],[Plano de Contas]],BASE!$B$3:$F$119,4,FALSE),"") -> 1 - CPV | K4: =IFERROR(VLOOKUP(DESPESAS[[#This Row],[Plano de Contas]],BASE!$B$3:$H$119,5,FALSE),"") -> COMPRAS | L4: =IFERROR(VLOOKUP(DESPESAS[[#This Row],[Plano de Contas]],BASE!$B$3:$H$119,6,FALSE),"") -> 0 | M4: =VLOOKUP(DESPESAS[[#This Row],[Plano de Contas]],BASE!$B$3:$H$119,7,FALSE) -> MYLENA
A5: 53685 | B5: LAY | C5: 002691 | D5: 46065 | E5: BONACK E SANCHES LTDA ME | F5: 1425.6 | G5: 3.4.2.6 - Compras - Pés/Mecanismos/Bases | H5: =VLOOKUP(DESPESAS[[#This Row],[Plano de Contas]],BASE!$B$3:$D$119,3,FALSE) -> Compras - Pés/Mecanismos/Bases | I5: =IFERROR(VLOOKUP(DESPESAS[[#This Row],[Fornecedor]],Tabela2[],2,FALSE),"") | J5: =IFERROR(VLOOKUP(DESPESAS[[#This Row],[Plano de Contas]],BASE!$B$3:$F$119,4,FALSE),"") -> 1 - CPV | K5: =IFERROR(VLOOKUP(DESPESAS[[#This Row],[Plano de Contas]],BASE!$B$3:$H$119,5,FALSE),"") -> COMPRAS | L5: =IFERROR(VLOOKUP(DESPESAS[[#This Row],[Plano de Contas]],BASE!$B$3:$H$119,6,FALSE),"") -> 0 | M5: =VLOOKUP(DESPESAS[[#This Row],[Plano de Contas]],BASE!$B$3:$H$119,7,FALSE) -> MYLENA
A6: 53687 | B6: KAR | C6: 130161 | D6: 46065 | E6: MANUFATURA DE BOTOES CARDENAS LTDA | F6: 967.68 | G6: 3.4.2.1 - Compras | H6: =VLOOKUP(DESPESAS[[#This Row],[Plano de Contas]],BASE!$B$3:$D$119,3,FALSE) -> Compras | I6: =IFERROR(VLOOKUP(DESPESAS[[#This Row],[Fornecedor]],Tabela2[],2,FALSE),"") | J6: =IFERROR(VLOOKUP(DESPESAS[[#This Row],[Plano de Contas]],BASE!$B$3:$F$119,4,FALSE),"") -> 1 - CPV | K6: =IFERROR(VLOOKUP(DESPESAS[[#This Row],[Plano de Contas]],BASE!$B$3:$H$119,5,FALSE),"") -> COMPRAS | L6: =IFERROR(VLOOKUP(DESPESAS[[#This Row],[Plano de Contas]],BASE!$B$3:$H$119,6,FALSE),"") -> 0 | M6: =VLOOKUP(DESPESAS[[#This Row],[Plano de Contas]],BASE!$B$3:$H$119,7,FALSE) -> MYLENA
A7: 53786 | B7: FK | C7: DIIH50 | D7: 46080 | E7: DIONIZIO PRIETO | F7: 100 | G7: 3.4.2.6 - Compras - Pés/Mecanismos/Bases | H7: =VLOOKUP(DESPESAS[[#This Row],[Plano de Contas]],BASE!$B$3:$D$119,3,FALSE) -> Compras - Pés/Mecanismos/Bases | I7: =IFERROR(VLOOKUP(DESPESAS[[#This Row],[Fornecedor]],Tabela2[],2,FALSE),"") | J7: =IFERROR(VLOOKUP(DESPESAS[[#This Row],[Plano de Contas]],BASE!$B$3:$F$119,4,FALSE),"") -> 1 - CPV | K7: =IFERROR(VLOOKUP(DESPESAS[[#This Row],[Plano de Contas]],BASE!$B$3:$H$119,5,FALSE),"") -> COMPRAS | L7: =IFERROR(VLOOKUP(DESPESAS[[#This Row],[Plano de Contas]],BASE!$B$3:$H$119,6,FALSE),"") -> 0 | M7: =VLOOKUP(DESPESAS[[#This Row],[Plano de Contas]],BASE!$B$3:$H$119,7,FALSE) -> MYLENA
A8: 53801 | B8: KOY | C8: 000008 | D8: 46080 | E8: CRIATIVE MOVEIS PLANEJADOS LTDA | F8: 20 | G8: 3.4.2.1 - Compras | H8: =VLOOKUP(DESPESAS[[#This Row],[Plano de Contas]],BASE!$B$3:$D$119,3,FALSE) -> Compras | I8: =IFERROR(VLOOKUP(DESPESAS[[#This Row],[Fornecedor]],Tabela2[],2,FALSE),"") | J8: =IFERROR(VLOOKUP(DESPESAS[[#This Row],[Plano de Contas]],BASE!$B$3:$F$119,4,FALSE),"") -> 1 - CPV | K8: =IFERROR(VLOOKUP(DESPESAS[[#This Row],[Plano de Contas]],BASE!$B$3:$H$119,5,FALSE),"") -> COMPRAS | L8: =IFERROR(VLOOKUP(DESPESAS[[#This Row],[Plano de Contas]],BASE!$B$3:$H$119,6,FALSE),"") -> 0 | M8: =VLOOKUP(DESPESAS[[#This Row],[Plano de Contas]],BASE!$B$3:$H$119,7,FALSE) -> MYLENA
A9: 53812 | B9: KAR | C9: 000010 | D9: 46080 | E9: CRIATIVE MOVEIS PLANEJADOS LTDA | F9: 865.7 | G9: 3.4.2.6 - Compras - Pés/Mecanismos/Bases | H9: =VLOOKUP(DESPESAS[[#This Row],[Plano de Contas]],BASE!$B$3:$D$119,3,FALSE) -> Compras - Pés/Mecanismos/Bases | I9: =IFERROR(VLOOKUP(DESPESAS[[#This Row],[Fornecedor]],Tabela2[],2,FALSE),"") | J9: =IFERROR(VLOOKUP(DESPESAS[[#This Row],[Plano de Contas]],BASE!$B$3:$F$119,4,FALSE),"") -> 1 - CPV | K9: =IFERROR(VLOOKUP(DESPESAS[[#This Row],[Plano de Contas]],BASE!$B$3:$H$119,5,FALSE),"") -> COMPRAS | L9: =IFERROR(VLOOKUP(DESPESAS[[#This Row],[Plano de Contas]],BASE!$B$3:$H$119,6,FALSE),"") -> 0 | M9: =VLOOKUP(DESPESAS[[#This Row],[Plano de Contas]],BASE!$B$3:$H$119,7,FALSE) -> MYLENA
A10: 53839 | B10: KAR | C10: 008036 | D10: 46087 | E10: MUNDIAL ACO COMERCIO DE FERRAGENS LTDA | F10: 25 | G10: 3.4.2.1 - Compras | H10: =VLOOKUP(DESPESAS[[#This Row],[Plano de Contas]],BASE!$B$3:$D$119,3,FALSE) -> Compras | I10: =IFERROR(VLOOKUP(DESPESAS[[#This Row],[Fornecedor]],Tabela2[],2,FALSE),"") | J10: =IFERROR(VLOOKUP(DESPESAS[[#This Row],[Plano de Contas]],BASE!$B$3:$F$119,4,FALSE),"") -> 1 - CPV | K10: =IFERROR(VLOOKUP(DESPESAS[[#This Row],[Plano de Contas]],BASE!$B$3:$H$119,5,FALSE),"") -> COMPRAS | L10: =IFERROR(VLOOKUP(DESPESAS[[#This Row],[Plano de Contas]],BASE!$B$3:$H$119,6,FALSE),"") -> 0 | M10: =VLOOKUP(DESPESAS[[#This Row],[Plano de Contas]],BASE!$B$3:$H$119,7,FALSE) -> MYLENA
A11: 53989 | B11: KAR | C11: 045593 | D11: 46111 | E11: GIROTEC MOVEIS E METALURGICA LTDA | F11: 1221.65 | G11: 3.4.2.6 - Compras - Pés/Mecanismos/Bases | H11: =VLOOKUP(DESPESAS[[#This Row],[Plano de Contas]],BASE!$B$3:$D$119,3,FALSE) -> Compras - Pés/Mecanismos/Bases | I11: =IFERROR(VLOOKUP(DESPESAS[[#This Row],[Fornecedor]],Tabela2[],2,FALSE),"") | J11: =IFERROR(VLOOKUP(DESPESAS[[#This Row],[Plano de Contas]],BASE!$B$3:$F$119,4,FALSE),"") -> 1 - CPV | K11: =IFERROR(VLOOKUP(DESPESAS[[#This Row],[Plano de Contas]],BASE!$B$3:$H$119,5,FALSE),"") -> COMPRAS | L11: =IFERROR(VLOOKUP(DESPESAS[[#This Row],[Plano de Contas]],BASE!$B$3:$H$119,6,FALSE),"") -> 0 | M11: =VLOOKUP(DESPESAS[[#This Row],[Plano de Contas]],BASE!$B$3:$H$119,7,FALSE) -> MYLENA
A12: 54001 | B12: LAY | C12: 000015 | D12: 46112 | E12: CRIATIVE MOVEIS PLANEJADOS LTDA | F12: 1320.1 | G12: 3.4.2.1 - Compras | H12: =VLOOKUP(DESPESAS[[#This Row],[Plano de Contas]],BASE!$B$3:$D$119,3,FALSE) -> Compras | I12: =IFERROR(VLOOKUP(DESPESAS[[#This Row],[Fornecedor]],Tabela2[],2,FALSE),"") | J12: =IFERROR(VLOOKUP(DESPESAS[[#This Row],[Plano de Contas]],BASE!$B$3:$F$119,4,FALSE),"") -> 1 - CPV | K12: =IFERROR(VLOOKUP(DESPESAS[[#This Row],[Plano de Contas]],BASE!$B$3:$H$119,5,FALSE),"") -> COMPRAS | L12: =IFERROR(VLOOKUP(DESPESAS[[#This Row],[Plano de Contas]],BASE!$B$3:$H$119,6,FALSE),"") -> 0 | M12: =VLOOKUP(DESPESAS[[#This Row],[Plano de Contas]],BASE!$B$3:$H$119,7,FALSE) -> MYLENA
A13: 54003 | B13: KOY | C13: 000014 | D13: 46112 | E13: CRIATIVE MOVEIS PLANEJADOS LTDA | F13: 189.2 | G13: 3.4.2.1 - Compras | H13: =VLOOKUP(DESPESAS[[#This Row],[Plano de Contas]],BASE!$B$3:$D$119,3,FALSE) -> Compras | I13: =IFERROR(VLOOKUP(DESPESAS[[#This Row],[Fornecedor]],Tabela2[],2,FALSE),"") | J13: =IFERROR(VLOOKUP(DESPESAS[[#This Row],[Plano de Contas]],BASE!$B$3:$F$119,4,FALSE),"") -> 1 - CPV | K13: =IFERROR(VLOOKUP(DESPESAS[[#This Row],[Plano de Contas]],BASE!$B$3:$H$119,5,FALSE),"") -> COMPRAS | L13: =IFERROR(VLOOKUP(DESPESAS[[#This Row],[Plano de Contas]],BASE!$B$3:$H$119,6,FALSE),"") -> 0 | M13: =VLOOKUP(DESPESAS[[#This Row],[Plano de Contas]],BASE!$B$3:$H$119,7,FALSE) -> MYLENA
... A4126: 201601 | B4126: KAR | C4126: 876 | D4126: 46153 | E4126: ALFZ COMERCIO DE BALANCAS ltda | F4126: 365.6 | G4126: 3.4.4.1 - Manutenção de Equipamentos (Prod) | H4126: =VLOOKUP(DESPESAS[[#This Row],[Plano de Contas]],BASE!$B$3:$D$119,3,FALSE) -> Manutenção de Equipamentos (Prod) | I4126: =IFERROR(VLOOKUP(DESPESAS[[#This Row],[Fornecedor]],Tabela2[],2,FALSE),"") | J4126: =IFERROR(VLOOKUP(DESPESAS[[#This Row],[Plano de Contas]],BASE!$B$3:$F$119,4,FALSE),"") -> 3 - CUSTOS INDIRETOS | K4126: =IFERROR(VLOOKUP(DESPESAS[[#This Row],[Plano de Contas]],BASE!$B$3:$H$119,5,FALSE),"") -> MANUTENÇÃO / TI | L4126: =IFERROR(VLOOKUP(DESPESAS[[#This Row],[Plano de Contas]],BASE!$B$3:$H$119,6,FALSE),"") -> 0 | M4126: =VLOOKUP(DESPESAS[[#This Row],[Plano de Contas]],BASE!$B$3:$H$119,7,FALSE) -> RAFAEL

Sheet FORNECEDORES MANUTENÇÃO
A2: FORNECEDOR | B2: MÁQUINA
A3: NEW CORTS LTDA - ME | B3: ACRILICO
A4: RIZON IND. DE MAQUINAS E EQUIPAMENTOS | B4: CNC MADEIRAS
A5: BLUTECH MANUTENÇÃO DE EQUIPAMENTOS LTDA | B5: CNC TECIDO
A6: R&J EQUIPAMENTOS LTDA | B6: CNC TECIDO
A7: ELAINE CRISTINA TAROCO SANTOS & CIA LTDA | B7: COMPONENTES T.I
A8: PANIR EQUIPAMENTOS LTDA | B8: COMPRESSORES
A9: PPO COMPRESSORES LTDA | B9: COMPRESSORES
A10: CASA DE FERRAGEM NISHIMOTO | B10: FERRAGENS GERAIS
A11: FERRAMENTAS GERAIS COMERCIO IMP DE FERRAM. E MAQUI | B11: FERRAGENS GERAIS
A12: RODRIGUES & LIMA FERRAGENS DE FERRAMENTAS LTDA - M | B12: FERRAGENS GERAIS
A13: A D TIZO JUNIOR - FERRAMENTAS ME | B13: GRAMPEADORES IMECO
... A51: EBANX LTDA | B51: SITE

Sheet BASE
B2: Plano de Contas | C2: Código | D2: Descrição | E2: CENTRO DE CUSTO | F2: SETOR | G2: TAG | H2: RESPONSÁVEL
B3: 1.3.1 - Maquinas e Equipamentos | C3: 1.3.1 | D3: Maquinas e Equipamentos | E3: 9 - INVESTIMENTOS | F3: MANUTENÇÃO / TI | H3: RAFAEL
B4: 1.3.2 - Moveis e Utensilios | C4: 1.3.2 | D4: Moveis e Utensilios | E4: 9 - INVESTIMENTOS | F4: ADMINISTRATIVO | H4: RAFAEL
B5: 1.3.3 - Computadores e Periféricos | C5: 1.3.3 | D5: Computadores e Periféricos | E5: 9 - INVESTIMENTOS | F5: MANUTENÇÃO / TI | H5: RAFAEL
B6: 1.3.4 - Construções e Reformas | C6: 1.3.4 | D6: Construções e Reformas | E6: 9 - INVESTIMENTOS | F6: MANUTENÇÃO / TI | H6: FÁBIO
B7: 1.3.5 - Consórcios | C7: 1.3.5 | D7: Consórcios | E7: 9 - INVESTIMENTOS | F7: FINANCEIRO | H7: FÁBIO
B8: 1.3.6 - Investimento em Ativos | C8: 1.3.6 | D8: Investimento em Ativos | E8: 9 - INVESTIMENTOS | F8: FINANCEIRO | H8: FÁBIO
B9: 2.1.4 - Aquisição de Financiamento | C9: 2.1.4 | D9: Aquisição de Financiamento | H9: NINGUÉM
B10: 2.9.6 - Impostos a recolher | C10: 2.9.6 | D10: Impostos a recolher | E10: 0 - TRIBUTOS | F10: FINANCEIRO | H10: LETÍCIA
B11: 3.3.1 - Simples Nacional | C11: 3.3.1 | D11: Simples Nacional | E11: 0 - TRIBUTOS | F11: FINANCEIRO | H11: LETÍCIA
B12: 3.3.2 - ICMS | C12: 3.3.2 | D12: ICMS | E12: 0 - TRIBUTOS | F12: FINANCEIRO | H12: LETÍCIA
B13: 3.3.3 - PIS | C13: 3.3.3 | D13: PIS | E13: 0 - TRIBUTOS | F13: FINANCEIRO | H13: LETÍCIA
B14: 3.3.4 - COFINS | C14: 3.3.4 | D14: COFINS | E14: 0 - TRIBUTOS | F14: FINANCEIRO | H14: LETÍCIA
B15: 3.3.7 - IPI | C15: 3.3.7 | D15: IPI | E15: 0 - TRIBUTOS | F15: FINANCEIRO | H15: LETÍCIA
B16: 3.3.8 - Outros Impostos | C16: 3.3.8 | D16: Outros Impostos | E16: 0 - TRIBUTOS | F16: FINANCEIRO | H16: LETÍCIA
B17: 3.4.2.1 - Compras | C17: 3.4.2.1 | D17: Compras | E17: 1 - CPV | F17: COMPRAS | H17: MYLENA
B18: 3.4.2.2 - Frete sobre Compras | C18: 3.4.2.2 | D18: Frete sobre Compras | E18: 1 - CPV | F18: COMPRAS | H18: MYLENA
B19: 3.4.2.4 - Compras - Tecido | C19: 3.4.2.4 | D19: Compras - Tecido | E19: 1 - CPV | F19: COMPRAS | H19: MYLENA
B20: 3.4.2.6 - Compras - Pés/Mecanismos/Bases | C20: 3.4.2.6 | D20: Compras - Pés/Mecanismos/Bases | E20: 1 - CPV | F20: COMPRAS | H20: MYLENA
B21: 3.4.3.1 - Energia Eletrica (Prod) | C21: 3.4.3.1 | D21: Energia Eletrica (Prod) | E21: 2 - CUSTOS DIRETOS | F21: PRODUÇÃO | H21: RAFAEL
B22: 3.4.3.10 - Seguro de Vida MOD | C22: 3.4.3.10 | D22: Seguro de Vida MOD | E22: 2 - CUSTOS DIRETOS | F22: DH | G22: CUSTO MÃO DE OBRA DIRETA | H22: RAFAEL
B23: 3.4.3.11 - FGTS MOD | C23: 3.4.3.11 | D23: FGTS MOD | E23: 2 - CUSTOS DIRETOS | F23: DH | G23: CUSTO MÃO DE OBRA DIRETA | H23: RAFAEL
B24: 3.4.3.12 - INSS MOD | C24: 3.4.3.12 | D24: INSS MOD | E24: 2 - CUSTOS DIRETOS | F24: DH | G24: CUSTO MÃO DE OBRA DIRETA | H24: RAFAEL
B25: 3.4.3.13 - Férias MOD | C25: 3.4.3.13 | D25: Férias MOD | E25: 2 - CUSTOS DIRETOS | F25: DH | G25: CUSTO MÃO DE OBRA DIRETA | H25: RAFAEL
B26: 3.4.3.14 - Medicina e Segurança do Trabalho MOD | C26: 3.4.3.14 | D26: Medicina e Segurança do Trabalho MOD | E26: 3 - CUSTOS INDIRETOS | F26: DH | G26: CUSTO MÃO DE OBRA DIRETA | H26: RAFAEL
B27: 3.4.3.2 - Material de Expediente (Prod) | C27: 3.4.3.2 | D27: Material de Expediente (Prod) | E27: 2 - CUSTOS DIRETOS | F27: PRODUÇÃO | H27: RAFAEL
B28: 3.4.3.3 - EPIs/Uniformes (Prod) | C28: 3.4.3.3 | D28: EPIs/Uniformes (Prod) | E28: 2 - CUSTOS DIRETOS | F28: COMPRAS | H28: RAFAEL
B29: 3.4.3.4 - Salarios e Ordenados MOD | C29: 3.4.3.4 | D29: Salarios e Ordenados MOD | E29: 2 - CUSTOS DIRETOS | F29: DH | G29: CUSTO MÃO DE OBRA DIRETA | H29: RAFAEL
B30: 3.4.3.5 - Horas Extras MOD | C30: 3.4.3.5 | D30: Horas Extras MOD | E30: 2 - CUSTOS DIRETOS | F30: DH | G30: CUSTO MÃO DE OBRA DIRETA | H30: RAFAEL
B31: 3.4.3.7 - Gratificacoes MOD | C31: 3.4.3.7 | D31: Gratificacoes MOD | E31: 2 - CUSTOS DIRETOS | F31: DH | G31: CUSTO MÃO DE OBRA DIRETA | H31: RAFAEL
B32: 3.4.3.8 - Rescisões MOD | C32: 3.4.3.8 | D32: Rescisões MOD | E32: 2 - CUSTOS DIRETOS | F32: DH | H32: RAFAEL
B33: 3.4.3.9 - Assistência Médica MOD | C33: 3.4.3.9 | D33: Assistência Médica MOD | E33: 2 - CUSTOS DIRETOS | F33: DH | G33: CUSTO MÃO DE OBRA DIRETA | H33: RAFAEL
B34: 3.4.4.1 - Manutenção de Equipamentos (Prod) | C34: 3.4.4.1 | D34: Manutenção de Equipamentos (Prod) | E34: 3 - CUSTOS INDIRETOS | F34: MANUTENÇÃO / TI | H34: RAFAEL
B35: 3.4.4.8 - Assistência Médica CIF | C35: 3.4.4.8 | D35: Assistência Médica CIF | E35: 3 - CUSTOS INDIRETOS | F35: DH | H35: RAFAEL
